Workbook

Sheet INICIO
A1: 0

Sheet DEZEMBRO19
A1: CLIENTE | B1: Data Entr | C1: Data Prod | D1: OC | E1: MATERIAL | F1: CÓDIGO | G1: ETIQUETA | H1: QUANT | I1: OK | J1: TEMPO | K1: QUANT | L1: OBSERVAÇÕES
A2: MODAZINE | B2: 43798 | C2: 43801 | D2: 1068 | E2: C. VER | F2: 2017 | G2: 33X21 | H2: 200000 | I2: OK | L2: FACA
A3: MODAZINE | B3: 43798 | C3: 43801 | D3: 1068 | E3: C.AMA | F3: 1785 | G3: 33X21 | H3: 30000 | I3: OK | L3: FACA
A4: BOI SUL | B4: 43801 | C4: 43790 | D4: 937 | E4: SYP | F4: 2631 | G4: 75X263 | H4: 5350 | I4: OK | L4: beta
A5: BOI SUL | B5: 43801 | C5: 43797 | D5: 937 | E5: BOPP BORR | F5: 2632 | G5: 103X94 | H5: 5000 | I5: OK | L5: BETA
A6: HYVA | B6: 43801 | C6: 43726 | D6: 855 | E6: TAG | F6: 2550 | G6: 100X70 | H6: 20000 | I6: OK | L6: BETA
A7: HYVA | B7: 43801 | C7: 43801 | D7: 855 | E7: COU BORR | F7: 2244 | G7: 100X60 | H7: 5000 | I7: OK | L7: FACA
A8: ESSENCIA JOVEM | B8: 43801 | C8: 43801 | D8: 1095 | E8: COUCHE | F8: 855 | G8: 50X40 | H8: 40000 | I8: OK | L8: FACA
A9: SIMONE | B9: 43801 | C9: 43801 | D9: 1101 | E9: NYLON | F9: 2600 | G9: 29X76 | H9: 5500 | I9: OK | L9: FACA
A10: DUKE | B10: 43801 | C10: 43801 | D10: 1076 | E10: COUCHE | F10: 2891 | G10: 60X60 | H10: 1000 | I10: OK | L10: BETA
A11: LAB. CESAR COSTA | B11: 43802 | C11: 43801 | D11: 942 | E11: COUCHE | F11: 2086 | G11: 45X25 | H11: 11000 | I11: OK | L11: BETA
A12: BRASSUD | B12: 43803 | C12: 43802 | D12: 847 | E12: COUCHE | F12: 1960 | G12: 35X40 | H12: 40000 | I12: OK | L12: FACA
A13: CODETECH | B13: 43804 | C13: 43802 | D13: 1087 | E13: COUCHE | F13: 869 | G13: 33X25 | H13: 50000 | I13: OK | L13: FACA
... A36: FRIZZO | B36: 43811 | C36: 43804 | D36: 1116 | E36: COUCHE | F36: 2762 | G36: 25X16 | H36: 100000 | I36: ok | L36: BETA
A37: BIOLUZ | B37: 43811 | D37: 1118 | E37: COUCHE | F37: 2664 | G37: 15X30 | H37: 30000 | I37: OK | L37: FACA
A38: CAPPELLETTI | B38: 43811 | C38: 43803 | D38: 1119 | E38: COUCHE | F38: 838 | G38: 100X40 | H38: 20000 | I38: OK | L38: FACA
A39: TEFFA | B39: 43811 | C39: 43810 | D39: 1120 | E39: COUCHE | F39: 2315 | G39: 70X25 | H39: 10000 | I39: OK | L39: BETA
A40: SECTA | B40: 43811 | C40: 43804 | D40: 1121 | E40: BOPP ACR | F40: 1599 | G40: 90X25 | H40: 5000 | I40: OK | L40: FACA
A41: SHOWCOLATS | B41: 43811 | C41: 43804 | D41: 1122 | E41: COUCHE | F41: 2664 | G41: 15X30 | H41: 200 | I41: OK | L41: FACA
A42: ALTAIR | B42: 43804 | C42: 43803 | D42: 1126 | E42: C.BORR | F42: 2438 | G42: 100X50 | H42: 15200 | I42: OK | L42: FACA
A43: ALTAIR | B43: 43804 | C43: 43803 | D43: 1126 | E43: C.BORR | F43: 2908 | G43: 50X30 | H43: 10000 | I43: OK | L43: FACA
A44: ARCO | B44: 43812 | C44: 43803 | D44: 852 | E44: COUCHE | F44: 2604 | G44: 105X55 | H44: 20800 | I44: OK | L44: SEPARAR
A45: GRAFICA DEZ | B45: 43812 | C45: 43812 | D45: 1111 | E45: COUCHE | F45: 2604 | G45: 105X55 | H45: 35000 | L45: SEPARAR
A46: FRIZZO | B46: 43812 | C46: 43805 | D46: 1106 | E46: COUCHE | F46: 869 | G46: 33X25 | H46: 204500 | I46: OK | L46: FACA
A47: ESTOQUE | B47: 43804 | C47: 43804 | D47: 1106 | E47: COUCHE | F47: 869 | G47: 33X25 | H47: 103500 | I47: OK | L47: FACA
A48: CHEIA DE CHARME | B48: 43812 | C48: 43804 | D48: 1127 | E48: COUCHE | F48: 869 | G48: 33X25 | H48: 12000 | I48: OK | L48: FACA
A49: EDEVANDRO | B49: 43812 | C49: 43812 | D49: 1128 | E49: COUCHE | F49: 2907 | G49: 50X120 | H49: 5000 | I49: OK | L49: BETA
A50: EDEVANDRO | B50: 43812 | C50: 43812 | D50: 1128 | E50: COUCHE | F50: 2328 | G50: 50X120 | H50: 5000 | I50: OK | L50: BETA
A51: DEKOS | B51: 43810 | C51: 43815 | D51: 1129 | E51: COUCHE | F51: 2102 | G51: 110X62 | H51: 19500 | I51: ok | L51: SUPERFLEXO
A52: KIPERFIL | B52: 43804 | C52: 43804 | D52: 1130 | E52: COUCHE | F52: 838 | G52: 100X40 | H52: 10000 | I52: OK | L52: FACA
A53: CBL | B53: 43805 | C53: 43805 | D53: 1131 | E53: COUCHE | F53: 1350 | G53: 50X35 | H53: 4000 | I53: OK | L53: BETA
A54: LAMINA | B54: 43814 | C54: 43810 | D54: 836 | E54: COUCHE | F54: 885 | G54: 70X50 | H54: 65000 | I54: OK | L54: FACA
A55: SHOWCOLATS | B55: 43822 | C55: 43819 | D55: 1123 | E55: COUCHE | F55: 2905 | G55: 25X25 | H55: 10000 | I55: OK | L55: SERA PRODUZIDO FORA
A56: SHOWCOLATS | B56: 43822 | C56: 43819 | D56: 1136 | E56: COUCHE | F56: 2906 | G56: 35X35 | H56: 11000 | I56: OK | L56: SERA PRODUZIDO FORA
A57: CASA E CIA | B57: 43815 | C57: 43803 | D57: 1094 | E57: C.AMA | F57: 2040 | G57: 40X30 | H57: 30000 | I57: OK | L57: BETA
... A71: FRIZZO | B71: 43816 | C71: 43816 | D71: 1139 | E71: COUCHE | F71: 2913 | G71: 100X100 | H71: 5000 | I71: OK | L71: BETA
A72: SUPERFLEXO | B72: 43815 | C72: 43816 | D72: 1185 | E72: COUCHE | F72: 1126 | G72: 100X100 | H72: 19000 | L72: SEPARAR
A73: QUALYFOODS | B73: 43816 | C73: 43810 | D73: 1140 | E73: COUCHE | F73: 1468 | G73: 100X75 | H73: 25000 | I73: ok | L73: FACA
A74: FRIZZO | B74: 43796 | C74: 43805 | D74: 1054 | E74: COUCHE | F74: 2186 | G74: 90X40 | H74: 69000 | I74: OK | L74: SEPARAR
A75: GRAFICA DEZ | B75: 43789 | C75: 43805 | D75: 1056 | E75: COUCHE | F75: 2186 | G75: 90X40 | H75: 71400 | I75: OK | L75: SERA PRODUZIDA FORA
...

Sheet JANEIRO20
A1: CLIENTE | B1: Data Entr | C1: Data Prod | D1: OC | E1: MATERIAL | F1: CÓDIGO | G1: ETIQUETA | H1: QUANT | I1: OK | J1: OBSERVAÇÕES | K1: TAMANHO | L1: METRO
A2: IND. MALHAS | B2: 43472 | C2: 43836 | D2: 1093 | E2: C.AMA | F2: 2061 | G2: 30X40 | H2: 30000 | I2: OK | J2: BETA | K2: 70 | L2: 645
A3: SULPACK | B3: 43472 | C3: 43836 | D3: 1184 | E3: BOPP | F3: 1401 | G3: 50X22 | H3: 9000 | I3: OK | J3: BETA | K3: 110 | L3: 108
A4: JETTA | B4: 43473 | C4: 43837 | D4: 1174 | E4: COUCHE | F4: 744 | G4: 100X70 | H4: 8000 | I4: OK | J4: BETA | K4: 105 | L4: 576
A5: JETTA | B5: 43473 | C5: 43837 | D5: 1174 | E5: COUCHE | F5: 2266 | G5: 90X25 | H5: 80000 | I5: OK | J5: FACA | K5: 95 | L5: 2240
A6: COESTER | B6: 43473 | C6: 43837 | D6: 1194 | E6: BOPP | F6: 1483 | G6: 100X40 | H6: 5000 | I6: OK | J6: FACA | K6: 105 | L6: 215
A7: LAIMED | B7: 43473 | C7: 43836 | D7: 1196 | E7: COUCHE | F7: 2927 | G7: 90X85 | H7: 5000 | I7: OK | J7: BETA | K7: 95 | L7: 440
A8: LAIMED | B8: 43473 | C8: 43836 | D8: 1196 | E8: COUCHE | F8: 2788 | G8: 50X75 | H8: 5000 | I8: OK | J8: BETA | K8: 60 | L8: 390
A9: CALERA | B9: 43473 | C9: 43837 | D9: 1197 | E9: BOPP | F9: 2490 | G9: 64X10 | H9: 30000 | I9: OK | J9: FACA | K9: 70 | L9: 396
A10: RESET | B10: 43473 | C10: 43838 | D10: 1198 | E10: COUCHE | F10: 869 | G10: 33X25 | H10: 50000 | I10: OK | J10: FACA | K10: 110 | L10: 470
A11: RESET | B11: 43473 | C11: 43838 | D11: 1198 | E11: COUCHE | F11: 855 | G11: 50X40 | H11: 46000 | I11: OK | J11: FACA | K11: 108 | L11: 840
A12: DANI | B12: 43474 | C12: 43839 | D12: 1199 | E12: COUCHE | F12: 838 | G12: 100X40 | H12: 31000 | I12: OK | J12: FACA | K12: 105 | L12: 1260
A13: G3 | B13: 43474 | C13: 43837 | D13: 1201 | E13: COUCHE | F13: 744 | G13: 100X70 | H13: 5000 | I13: OK | J13: BETA | K13: 105 | L13: 360
... A19: MUNDIAL | B19: 43478 | C19: 43839 | D19: 1208 | E19: C.BORR | F19: 2620 | G19: 100X120 | H19: 1750 | I19: OK | J19: BETA | K19: 105 | L19: 217
A20: CODETECH | B20: 43478 | C20: 43847 | D20: 1210 | E20: CINZA | F20: 2922 | G20: 100X150 | H20: 3000 | I20: OK | J20: BETA | K20: CINZA | L20: 459
A21: GRAFICA DEZ | B21: 43474 | C21: 43845 | D21: 1211 | E21: CINZA | F21: 2525 | G21: 105X1000 | H21: 1000 | I21: OK | J21: PINTAR
A22: GRAFICA DEZ | B22: 43474 | C22: 43845 | D22: 1211 | E22: AMARELO | F22: 2525 | G22: 105X1000 | H22: 1000 | I22: OK | J22: PINTAR
A23: FRIZZO | B23: 43475 | C23: 43840 | D23: 1212 | E23: COUCHE | F23: 879 | G23: 100X60 | H23: 20000 | I23: OK | J23: FACA | K23: 105 | L23: 1250
A24: FRIZZO | B24: 43475 | C24: 43843 | D24: 1213 | E24: COUCHE | F24: 2762 | G24: 25X16 | H24: 100000 | I24: OK | J24: FACA | K24: 105 | L24: 450
A25: FRIZZO | B25: 43478 | C25: 43843 | D25: 1214 | E25: COUCHE | F25: 869 | G25: 33X25 | H25: 210000 | I25: OK | J25: FACA | K25: 110 | L25: 1880
A26: MAR AZUL | B26: 43478 | C26: 43839 | D26: 1215 | E26: BOPP | F26: 2175 | G26: 30X80 | H26: 5000 | I26: OK | J26: BETA | K26: 100 | L26: 85
A27: WINELANDS | B27: 43844 | C27: 43840 | D27: 1219 | E27: COUCHE | F27: 2149 | G27: 70X40 | H27: 10000 | I27: OK | J27: BETA | K27: 75 | L27: 430
A28: CATAFESTA | B28: 43845 | C28: 43843 | D28: 1220 | E28: COUCHE | F28: 822 | G28: 50X50 | H28: 15000 | I28: OK | J28: FACA | K28: 108 | L28: 400
A29: FRIZZO | B29: 43480 | C29: 43840 | D29: 1216 | E29: COUCHE | F29: 822 | G29: 50X50 | H29: 50000 | I29: OK | J29: FACA | K29: 108 | L29: 1325 | M29: AUTOMATIZA
A30: ESTERELIZARE | B30: 43480 | C30: 43846 | D30: 1200 | E30: COUCHE | F30: 2913 | G30: 100X100 | H30: 50000 | I30: OK | J30: SERA PRODUZIDA FORA | K30: 108 | L30: 6000
A31: ESTERELIZARE | B31: 43480 | C31: 43846 | D31: 1200 | E31: COUCHE | F31: 2691 | G31: 100X50 | H31: 100000 | I31: OK | J31: SERA PRODUZIDA FORA | K31: 105 | L31: 6000
A32: GRAFICA DEZ | B32: 43480 | C32: 43846 | D32: 1209 | E32: COUCHE | F32: 2913 | G32: 100X100 | H32: 52400 | I32: OK | J32: SERA PRODUZIDA FORA
A33: GRAFICA DEZ | B33: 43480 | C33: 43846 | D33: 1209 | E33: COUCHE | F33: 2691 | G33: 100X50 | H33: 100980 | I33: OK | J33: SERA PRODUZIDA FORA
A34: OMEGA | B34: 43845 | C34: 43844 | D34: 1221 | E34: C.BORR | F34: 2586 | G34: 50X70 | H34: 50000 | I34: OK | J34: FACA | K34: 110 | L34: 1850
A35: FRIZZO | B35: 43840 | C35: 43838 | D35: 1222 | E35: VERMELHO | F35: 1548 | G35: 13X13 | H35: 50000 | I35: OK | J35: BETA
A36: FERREIRA | B36: 43840 | C36: 43839 | D36: 1227 | E36: DFAM | F36: 2935 | G36: 100X80 | H36: 10000 | I36: OK | J36: FACA
A37: GRAFICA 10 | B37: 43854 | C37: 43860 | D37: 1228 | E37: COUCHE | F37: 2805 | G37: 100X50 | H37: 10340 | I37: OK | J37: BRASILEIRINHO
A38: UNIMED | B38: 43846 | C38: 43844 | D38: 1229 | E38: COUCHE | F38: 2740 | G38: 90X36 | H38: 10000 | I38: OK | J38: FACA | K38: 100 | L38: 400
A39: MODAZINE | B39: 43482 | C39: 43846 | D39: 1206 | E39: TAG | F39: 2272 | G39: 35X62 | H39: 80000 | I39: OK | J39: SERA PRODUZIDA FORA
A40: GRAFICA DEZ | B40: 43482 | C40: 43846 | D40: 1206 | E40: TAG | F40: 2272 | G40: 35X62 | H40: 88000 | I40: OK | J40: SERA PRODUZIDA FORA
A41: MERIDIANO | B41: 43847 | C41: 43840 | D41: 1223 | E41: COUCHE | F41: 1018 | G41: 80X65 | H41: 6000 | I41: OK | J41: BETA | K41: 85 | L41: 410
A42: CODETECH | B42: 43847 | C42: 43840 | D42: 1226 | E42: COUCHE | F42: 2934 | G42: 20X40 | H42: 12000 | I42: OK | J42: BETA | K42: 90 | L42: 130
A43: MODAZINE | B43: 43853 | C43: 43846 | D43: 1230 | E43: TAG | F43: 2272 | G43: 35X62 | H43: 80000 | I43: OK | J43: SERA PRODUZIDA FORA
A44: GRAFICA DEZ | B44: 43853 | C44: 43846 | D44: 1230 | E44: TAG | F44: 2272 | G44: 35X62 | H44: 86000 | I44: OK | J44: SERA PRODUZIDA FORA
A45: SHOWCOLATS | B45: 43844 | C45: 43838 | D45: 1231 | E45: COUCHE | F45: 2937 | G45: 20X30 | H45: 300 | I45: OK | J45: BETA
...

Sheet FEVEREIRO20
A1: CLIENTE | B1: Data Entr | C1: Data Prod | D1: OC | E1: MATERIAL | F1: CÓDIGO | G1: ETIQUETA | H1: QUANT | I1: OK | J1: OBSERVAÇÕES | K1: TAMANHO | L1: METRO
A2: 3C | B2: 43874 | C2: 43866 | D2: 1309 | E2: REMOVIVEL | F2: 2987 | G2: 100X60 | H2: 5000 | I2: OK | J2: LARANJA
A3: GRAFICA DEZ | B3: 43874 | C3: 43866 | D3: 1314 | E3: REMOVIVEL | F3: 2381 | G3: 105X500 | H3: 500 | I3: OK | J3: LARANJA | L3: 43866
A4: DUKE | B4: 43864 | C4: 43864 | D4: 1310 | E4: COUCHE | F4: 2800 | G4: 45X45 | H4: 3000 | I4: OK | J4: BETA
A5: FRIZZO | B5: 43865 | C5: 43864 | D5: 1283 | E5: COUCHE | F5: 869 | G5: 33X25 | H5: 200000 | I5: OK | J5: FACA | K5: 110 | L5: 1880
A6: FRIZZO | B6: 43865 | C6: 43865 | D6: 1284 | E6: COUCHE | F6: 2664 | G6: 15X30 | H6: 200000 | I6: OK | J6: FACA | K6: 108 | L6: 1100
A7: IMEXPORT | B7: 43865 | C7: 43864 | D7: 1313 | E7: COUCHE | F7: 2854 | G7: 104X125 | H7: 5000 | I7: OK | J7: BETA
A8: GRAFICA DEZ | B8: 43868 | C8: 43888 | D8: 1315 | E8: TC | F8: 2749 | G8: 45X85 | H8: 11000 | I8: OK | J8: FARMBERRY
A9: G3 | B9: 43865 | C9: 43865 | D9: 1317 | E9: COUCHE | F9: 1397 | G9: 50X30 | H9: 35000 | I9: OK | J9: FACA
A10: HYVA | B10: 43866 | C10: 43864 | D10: 1320 | E10: C.BORR | F10: 2244 | G10: 100X60 | H10: 10000 | I10: OK | J10: FACA
A11: INJET | B11: 43866 | C11: 43866 | D11: 1321 | E11: B.BORR | F11: 2494 | G11: 25X25 | H11: 12400 | I11: OK | J11: BETA
A12: COMPUMIX | B12: 43866 | C12: 43865 | D12: 1333 | E12: COUCHE | F12: 1397 | G12: 50X30 | H12: 100000 | I12: OK | J12: FACA
A13: GRAFICA DEZ | B13: 43853 | C13: 43854 | D13: 1299 | E13: BOPP BORR | F13: 2669 | G13: 95X500 | H13: 4000 | I13: OK | J13: PINTAR 7 CORES
A14: FRIZZO | B14: 43867 | C14: 43864 | D14: 1326 | E14: COUCHE | F14: 1869 | G14: 33X21 | H14: 80000 | I14: OK | J14: FACA
A15: DIFLORES | B15: 43867 | C15: 43865 | D15: 1329 | E15: TAG | F15: 2993 | G15: 35X64 | H15: 30000 | I15: OK | J15: BETA
A16: FRIZZO | B16: 43867 | C16: 43875 | D16: 1330 | E16: COUCHE | F16: 2186 | G16: 90X40 | H16: 40000 | I16: OK | J16: FACA | M16: 15000 | N16: ESTOQUE
A17: PANIZZON | B17: 43864 | C17: 43864 | D17: 1334 | E17: COUCHE | F17: 1545 | G17: 100X68 | H17: 30000 | I17: OK | J17: FACA | K17: BRANCA
A18: PANIZZON | B18: 43864 | C18: 43864 | D18: 1334 | E18: COUCHE | F18: 2447 | G18: 100X68 | H18: 15000 | I18: OK | J18: FACA | K18: AMARELA
A19: PANIZZON | B19: 43864 | C19: 43881 | D19: 1334 | E19: COUCHE | F19: 2576 | G19: 100X68 | H19: 15000 | I19: OK | J19: FACA | K19: AZUL
A20: PANIZZON | B20: 43867 | C20: 43881 | D20: 1334 | E20: COUCHE | F20: 2818 | G20: 100X68 | H20: 15000 | I20: OK | J20: FACA | K20: ROSA
A21: PANIZZON | B21: 43864 | C21: 43881 | D21: 1334 | E21: COUCHE | F21: 2448 | G21: 100X68 | H21: 15000 | I21: OK | J21: FACA | K21: VERDE
A22: GRAFICA DEZ | B22: 43867 | C22: 43881 | D22: 1336 | E22: COUCHE | F22: 2525 | G22: 105X1000 | H22: 1 | I22: OK | J22: ROSA
A23: SERRANA | B23: 43867 | C23: 43867 | D23: 1335 | E23: COUCHE | F23: 1273 | G23: 55X28 | H23: 24000 | I23: OK | J23: PERSONALIZAR
A24: CORSUL | B24: 43868 | C24: 43866 | D24: 1337 | E24: COUCHE | F24: 2347 | G24: 50X150 | H24: 5000 | I24: OK | J24: BETA
A25: SCARIOT | B25: 43868 | C25: 43867 | D25: 1338 | E25: COUCHE | F25: 2064 | G25: 35X64 | H25: 20000 | I25: OK | J25: BETA
A26: BOISUL | B26: 43868 | C26: 43867 | D26: 1339 | E26: B.BORR | F26: 2632 | G26: 103X94 | H26: 5000 | I26: OK | J26: BETA
A27: BOISUL | B27: 43868 | C27: 43867 | D27: 1339 | E27: COUCHE | F27: 2039 | G27: 40X55 | H27: 5000 | I27: OK | J27: FACA
A28: GRAFICA DEZ | B28: 43868 | C28: 43881 | D28: 1341 | E28: COUCHE | F28: 2525 | G28: 105X1000 | H28: 1 | I28: OK | J28: VERDE
A29: GRAFICA DEZ | B29: 43868 | C29: 43881 | D29: 1342 | E29: COUCHE | F29: 2525 | G29: 105X1000 | H29: 1 | I29: OK | J29: VERMELHO
A30: MALH.DALANE | B30: 43874 | C30: 43873 | D30: 1343 | E30: TAG | F30: 2476 | G30: 35X60 | H30: 75000 | I30: OK | J30: BETA
A31: FRIZZO | B31: 43868 | C31: 43865 | D31: 1344 | E31: COUCHE | F31: 1468 | G31: 100X75 | H31: 5000 | I31: OK | J31: FACA
A32: VF ACESSORIOS | B32: 43868 | C32: 43864 | D32: 1346 | E32: COUCHE | F32: 1403 | G32: 100X60 | H32: 5000 | I32: OK | J32: FACA
A33: FRIZZO | B33: 43868 | C33: 43868 | D33: 1347 | E33: BOPP | F33: 785 | G33: 100X20 | H33: 5000 | I33: OK | J33: BETA
... A38: CAPPELLETTI | B38: 43871 | C38: 43868 | D38: 1351 | E38: COUCHE | F38: 2714 | G38: 33X25 | H38: 10000 | I38: OK | J38: FACA
A39: CASA E CIA | B39: 43871 | C39: 43871 | D39: 1352 | E39: COUCHE | F39: 3011 | G39: 40X30 | H39: 30000 | I39: OK | J39: BETA | K39: VERMELHO
A40: GRAFICA DEZ | B40: 43871 | C40: 43881 | D40: 1353 | E40: COUCHE | F40: 2525 | G40: 105X1.000 | H40: 4 | I40: OK | J40: PINTAR 4 CORES
A41: GRAFICA DEZ | B41: 43871 | C41: 43873 | D41: 1354 | E41: BOPP | F41: 2798 | G41: 78X30 | H41: 28400 | I41: OK | J41: RONI
A42: GRAFICA DEZ | B42: 43871 | C42: 43878 | D42: 1355 | E42: BOPP | F42: 2669 | G42: 95X1.000 | H42: 1 | I42: OK | J42: PINTAR 2 CORES | K42: FIXPAR
A43: TONIN | B43: 43871 | C43: 43868 | D43: 1356 | E43: COUCHE | F43: 3010 | G43: 100X180 | H43: 200 | I43: OK | J43: BETA
A44: PISO E TETO | B44: 43871 | C44: 43864 | D44: 1357 | E44: COUCHE | F44: 1869 | G44: 33X21 | H44: 10000 | I44: OK | J44: FACA
...

Sheet MARCO20
A1: CLIENTE | B1: Data Entr | C1: Data Prod | D1: OC | E1: MATERIAL | F1: CÓDIGO | G1: ETIQUETA | H1: QUANT | I1: OK | J1: OBSERVAÇÕES
A2: GRAFICA DEZ | B2: 43851 | C2: 43896 | D2: 1297 | E2: CASCA DE OVO | F2: 2976 | G2: 12,3X12,3 | H2: 15000 | I2: OK | J2: ATACASE
A3: HEMOVITA | B3: 43882 | C3: 43902 | D3: 3273 | E3: TERMICO | F3: 3082 | G3: 50X25 | H3: 64900 | I3: OK | J3: SEPARAR
A4: VITORIA | B4: 43900 | C4: 43902 | D4: 1404 | E4: TERMICO | F4: 3082 | G4: 50X25 | H4: 69600 | I4: OK | J4: CORTAR
A5: HEMOVITA | B5: 43882 | C5: 43900 | D5: 3273 | E5: TERMICO | F5: 3081 | G5: 100X120 | H5: 5000 | I5: OK
A6: VITORIA | B6: 43871 | C6: 43900 | D6: 1405 | E6: TERMICO | F6: 3081 | G6: 100X120 | H6: 7000 | I6: OK | J6: SEPARADA
A7: MODAZINE | B7: 43889 | C7: 43873 | D7: 3371 | E7: VERMELHA | F7: 2017 | G7: 33X21 | H7: 200000 | I7: OK | J7: FACA
A8: MODAZINE | B8: 43889 | C8: 43873 | D8: 3371 | E8: AMARELA | F8: 1785 | G8: 33X21 | H8: 155000 | I8: OK | J8: FACA
A9: CEACCATO | B9: 43893 | C9: 43892 | D9: 3363 | E9: COUCHE | F9: 3103 | G9: 90X53 | H9: 5000 | I9: OK | J9: BETA
A10: ECOMETAIS | B10: 43893 | C10: 43894 | D10: 3366 | E10: COUCHE | F10: 1007 | G10: 100X38 | H10: 30000 | I10: OK | J10: SEPARAR
A11: VITORIA | B11: 43894 | C11: 43892 | D11: 1397 | E11: COUCHE | F11: 1007 | G11: 100X38 | H11: 37000 | I11: OK | J11: CORTAR
A12: GRAFICA DEZ | B12: 43906 | C12: 43908 | D12: 1389 | E12: COUCHE | F12: 1904 | G12: 105X161 | H12: 11600 | I12: OK | J12: MODAZINE
A13: GRAFICA DEZ | B13: 43906 | C13: 43908 | D13: 1386 | E13: TAG | F13: 2272 | G13: 35X62 | H13: 167800 | I13: OK | J13: MODAZINE | K13: 47800 | L13: ESTOQ
A14: POLIBOM | B14: 43893 | C14: 43892 | D14: 3412 | E14: BOPP | F14: 2807 | G14: 100x68 | H14: 10000 | I14: OK | J14: FACA | M14: não foi dado entrada, só foi substituido para o cliente
A15: FRIZZO | B15: 43893 | C15: 43896 | D15: 3201 | E15: COUCHE | F15: 1106 | G15: 45X35 | H15: 47000 | I15: OK | J15: FACA NOVA
A16: CALSATY | B16: 43887 | C16: 43896 | D16: 3315 | E16: COUCHE | F16: 1106 | G16: 45X35 | H16: 6000 | I16: OK | J16: FACA NOVA
A17: HYVA | B17: 43866 | C17: 43893 | D17: 3382 | E17: TAG | F17: 2550 | G17: 100X70 | H17: 20000 | I17: OK | J17: BETA
A18: SUSIN | B18: 43895 | C18: 43893 | D18: 3386 | E18: COUCHE | F18: 343 | G18: 50X22 | H18: 5000 | I18: OK | J18: BETA
A19: MAR AZUL | B19: 43895 | C19: 43893 | D19: 3389 | E19: BOPP | F19: 2175 | G19: 30X80 | H19: 3000 | I19: OK | J19: BETA
A20: ZANLINE | B20: 43896 | C20: 43896 | D20: 3399 | E20: COUCHE | F20: 951 | G20: 100X150 | H20: 12190 | I20: OK | J20: SEPARAR
A21: VITORIA | B21: 43894 | C21: 43895 | D21: 1396 | E21: COUCHE | F21: 951 | G21: 100X150 | H21: 10000 | I21: OK | J21: CORTAR
A22: MODA VIVA | B22: 43896 | C22: 43896 | D22: 3405 | E22: COUCHE | F22: 2415 | G22: 33X39 | H22: 39000 | I22: OK | J22: SEPARAR
A23: VITORIA | B23: 43894 | C23: 43892 | D23: 1395 | E23: COUCHE | F23: 2415 | G23: 33X39 | H23: 25000 | I23: OK | J23: CORTAR
A24: LC SOLUCOES | B24: 43896 | C24: 43896 | D24: 3422 | E24: COUCHE | F24: 818 | G24: 50X70 | H24: 40800 | I24: OK | J24: FACA
A25: CODETECH | B25: 43896 | C25: 43896 | D25: 3430 | E25: COUCHE | F25: 1555 | G25: 50X30 | H25: 30000 | I25: OK | J25: FACA
A26: MUNDIAL | B26: 43899 | C26: 43901 | D26: 3413 | E26: C.BORR | F26: 2620 | G26: 100X120 | H26: 5250 | I26: OK | J26: VITORIA
... A34: FRIZZO | B34: 43888 | C34: 43901 | D34: 3279 | E34: COUCHE | F34: 2646 | G34: 50X35 | H34: 250000 | I34: OK | J34: GRAFICA DEZ
A35: GRAFICA DEZ | B35: 43887 | C35: 43901 | D35: 1376 | E35: COUCHE | F35: 2646 | G35: 50X35 | H35: 264400 | I35: OK
A36: GRAFICA DEZ | B36: 43889 | C36: 43894 | D36: 1372 | E36: COUCHE | F36: 2905 | G36: 25X25 | H36: 11300 | I36: OK | J36: SHOWCOLATS
A37: GRAFICA DEZ | B37: 43889 | C37: 43894 | D37: 1372 | E37: COUCHE | F37: 2906 | G37: 35X35 | H37: 30000 | I37: OK | J37: SHOWCOLATS
A38: GRAFICA DEZ | B38: 43889 | C38: 43894 | D38: 1372 | E38: COUCHE | F38: 3072 | G38: 45X45 | H38: 24000 | I38: OK | J38: SHOWCOLATS
A39: LC SOLUCOES | B39: 43899 | C39: 43894 | D39: 3429 | E39: TAG | F39: 625 | G39: 95X60 | H39: 5000 | I39: OK | J39: BETA
A40: RODER | B40: 43900 | C40: 43899 | D40: 3436 | E40: COUCHE | F40: 2209 | G40: 26X15 | H40: 20000 | I40: OK | J40: BETA
A41: RODER | B41: 43900 | C41: 43899 | D41: 3436 | E41: COUCHE | F41: 2528 | G41: 40X70 | H41: 10000 | I41: OK | J41: BETA
A42: FRIZZO | B42: 43900 | C42: 43899 | D42: 3438 | E42: COUCHE | F42: 879 | G42: 100X60 | H42: 40000 | I42: OK | J42: FACA
A43: SCUDO | B43: 43900 | C43: 43899 | D43: 3443 | E43: COUCHE | F43: 838 | G43: 100X40 | H43: 10000 | I43: OK | J43: FACA
A44: BERETTA | B44: 43900 | C44: 43900 | D44: 3449 | E44: BOPP | F44: 2490 | G44: 64X10 | H44: 6000 | I44: OK | J44: FACA
A45: BERETTA | B45: 43900 | C45: 43900 | D45: 3449 | E45: BOPP | F45: 2715 | G45: 64X10 | H45: 6000 | I45: OK | J45: FACA
A46: DOLCE VITA | B46: 43900 | C46: 43899 | D46: 3255 | E46: BOPP | F46: 3079 | G46: 40X40 | H46: 6000 | I46: OK | J46: BETA
A47: RIZZON | B47: 43901 | C47: 43900 | D47: 3455 | E47: COUCHE | F47: 1387 | G47: 100X68 | H47: 15000 | I47: OK | J47: FACA
...

Sheet JUNHO20
A1: CLIENTE | B1: Data Entr | C1: Data Prod | D1: O/F | E1: MATERIAL | F1: CÓDIGO | G1: ETIQUETA | H1: QUANT | I1: OK | J1: PRODUZIDO POR | K1: O/C | L1: VALOR
A2: MENG MORAN | B2: 43980 | C2: 43997 | D2: 3914 | E2: TC | F2: 3176 | G2: 50X90 | H2: 11700 | I2: OK | J2: G10 | K2: 1464 | L2: 1550
A3: JONES | B3: 43983 | C3: 43983 | D3: 3954 | E3: TERMICO | F3: 1442 | G3: 28X89 | H3: 25 | I3: OK | J3: LASER | L3: 300
A4: FRIZZO | B4: 43973 | D4: 3900 | E4: COUCHE | F4: 3174 | G4: 33X26 | H4: 50000 | I4: OK | J4: LASER
E5: REMOV | F5: 3175 | G5: 33X26 | H5: 44000 | I5: OK | J5: JUCA | K5: 1468 | L5: 580
A6: GLOBALTECH | B6: 43984 | C6: 43983 | D6: 3959 | E6: COUCHE | F6: 951 | G6: 100X150 | H6: 2000 | I6: OK | J6: LASER | L6: 210
A7: CODETECH | B7: 43984 | C7: 43984 | D7: 3971 | E7: BOPP | F7: 2719 | G7: 80X80 | H7: 5000 | I7: OK | J7: LASER | L7: 79
A8: AC LINK | B8: 43985 | C8: 43984 | D8: 3978 | E8: BOPP | F8: 2868 | G8: 85X10 | H8: 10000 | I8: OK | J8: LASER
E9: COUCHE | F9: 1397 | G9: 50X30 | H9: 10000 | I9: OK | J9: FACA | L9: 414
A10: SÃO CARLOS | B10: 43986 | C10: 43987 | D10: 3979 | E10: BOPP | F10: 1491 | G10: 100X23 | H10: 20000 | I10: OK | J10: JUCA | K10: 1466
E11: AMARELO | F11: 3162 | G11: 34X23 | H11: 16000 | I11: OK | J11: JUCA | K11: 1467
E12: VERMELHO | F12: 3163 | G12: 34X23 | H12: 16000 | I12: OK | J12: JUCA | K12: 1467 | L12: 668.7
A13: MAQENGE | B13: 43985 | C13: 43986 | D13: 3982 | E13: COUCHE | F13: 2720 | G13: 47X22 | H13: 25000 | I13: OK | J13: LASER | L13: 138
A14: GAMACOR | B14: 43986 | C14: 43985 | D14: 3984 | E14: COUCHE | F14: 1862 | G14: 100X35 | H14: 15000 | I14: OK | J14: LASER | L14: 358.5
A15: PLASMOSUL | B15: 43994 | C15: 43998 | D15: 3983 | E15: COUCHE | F15: 2559 | G15: 103X90 | H15: 4500 | I15: OK | J15: JUCA | K15: 1469 | L15: 415
A16: DILLIN | B16: 43987 | C16: 43984 | D16: 3985 | E16: COUCHE | F16: 1468 | G16: 100X75 | H16: 20000 | I16: OK | J16: LASER | L16: 1230
A17: BARAO | B17: 43990 | C17: 43987 | D17: 4000 | E17: COUCHE | F17: 3185 | G17: 50X100 | H17: 10400 | I17: OK | J17: LASER | L17: 240
A18: TRACIATTI | B18: 43987 | C18: 43984 | D18: 4002 | E18: COUCHE | F18: 951 | G18: 100X150 | H18: 5000 | I18: OK | J18: LASER | L18: 370
A19: BRASSUD | B19: 43987 | C19: 43984 | D19: 4009 | E19: COUCHE | F19: 1960 | G19: 35X40 | H19: 20000 | I19: OK | J19: FACA | L19: 442
A20: PETRYMAR | B20: 43997 | C20: 43984 | D20: 4010 | E20: COUCHE | F20: 753 | G20: 100X50 | H20: 20000 | I20: OK | J20: FACA | L20: 500
A21: POLIBOM | B21: 43985 | C21: 43985 | D21: 4019 | E21: COUCHE | F21: 2039 | G21: 40X55 | H21: 10500 | I21: OK | J21: FACA | L21: 171
A22: BOI SUL | B22: 43992 | C22: 43987 | D22: 4023 | E22: TAG | F22: 2631 | G22: 75X263 | H22: 5000 | I22: OK | J22: LASER
C23: 43985 | E23: COUCHE | F23: 2039 | G23: 40X55 | H23: 6000 | I23: OK | J23: FACA | L23: 938
A24: ZBM | B24: 43993 | C24: 43990 | D24: 4026 | E24: COUCHE | F24: 2811 | G24: 40X66 | H24: 5000 | I24: OK | J24: LASER
F25: 3035 | G25: 100X16 | H25: 5000 | I25: OK | J25: LASER
C26: 43985 | F26: 869 | G26: 33X25 | H26: 20000 | I26: OK | J26: FACA | L26: 148.203
A27: BANCO SANGUE | B27: 43986 | C27: 43985 | D27: 4027 | E27: BOPP | F27: 2467 | G27: 100X80 | H27: 4000 | I27: OK | J27: FACA | L27: 701.96
A28: SUPERLACK | B28: 43987 | C28: 43986 | D28: 4028 | E28: COUCHE | F28: 838 | G28: 100X40 | H28: 10000 | I28: OK | J28: FACA | L28: 134
A29: DOMAMA | B29: 43987 | C29: 43986 | D29: 4032 | E29: COUCHE | F29: 2515 | G29: 55X28 | H29: 10000 | I29: OK | J29: FACA | L29: 145
A30: RESET | B30: 43987 | C30: 43986 | D30: 4033 | E30: COUCHE | F30: 753 | G30: 100X50 | H30: 10400 | I30: OK | J30: FACA | L30: 230
A31: UP TO GO | B31: 43994 | C31: 43990 | D31: 4035 | E31: COUCHE | F31: 2971 | G31: 100X48 | H31: 200 | I31: OK | J31: LASER | L31: 5.42
A32: FRIZZO | B32: 43994 | D32: 4034 | E32: COUCHE | F32: 1126 | G32: 100X100 | H32: 5000 | I32: OK | J32: LASER | L32: 176.5
A33: SPIGOLON | B33: 43987 | C33: 43986 | D33: 4037 | E33: AMARELO | F33: 3189 | G33: 50X50 | H33: 6000 | I33: OK | J33: FACA | L33: 102.5
A34: ZANLINE | B34: 43997 | C34: 43998 | D34: 4038 | E34: COUCHE | F34: 951 | G34: 100X150 | H34: 10000 | I34: OK | J34: JUCA | K34: 1470 | L34: 670
C35: 43992 | D35: 4038 | E35: COUCHE | F35: 2266 | G35: 90X25 | H35: 7500 | I35: OK | J35: LASER | L35: 771.25
A36: ESTOQUE | B36: 43986 | C36: 43986 | D36: 0 | E36: COUCHE | F36: 838 | G36: 100X40 | H36: 17000 | I36: OK | J36: FACA
A37: HIDROQUIMICA | B37: 43997 | C37: 43992 | D37: 4041 | E37: BOPP | F37: 1255 | G37: 100X200 | H37: 5000 | I37: OK | J37: LASER | L37: 717.5
A38: VITAMED | B38: 43991 | C38: 43990 | D38: 4047 | E38: COUCHE | F38: 838 | G38: 100X40 | H38: 40000 | I38: OK | J38: FACA | L38: 1505
A39: CODETECH | B39: 43992 | C39: 43991 | D39: 4048 | E39: COUCHE | F39: 855 | G39: 50X40 | H39: 50000 | I39: OK | J39: FACA
E40: COUCHE | F40: 869 | G40: 33X25 | H40: 50000 | I40: OK | J40: FACA | L40: 675
...

Sheet JULHO20
A1: CLIENTE | B1: Data Entr | C1: Data Prod | D1: O/F | E1: MATERIAL | F1: CÓDIGO | G1: ETIQUETA | H1: MILHEIRO | I1: OK | J1: PRODUZIDO POR | K1: O/C | L1: VALOR
A2: BARAO | B2: 44012 | C2: 44005 | D2: 4143 | E2: COUCHE | F2: 822 | G2: 50X50 | H2: 51 | I2: OK | J2: FACA
C3: 44021 | D3: 3185 | E3: COUCHE | F3: 3185 | G3: 50X100 | H3: 56.4 | I3: OK | J3: G10 | K3: 1472
A4: POLIBOM | B4: 44012 | C4: 44013 | D4: 4194 | E4: COUCHE | F4: 3152 | G4: 100X200 | H4: 10 | I4: OK | J4: JUCA | K4: 1473
C5: 44011 | E5: COUCHE | F5: 2039 | G5: 40X55 | H5: 51 | I5: OK | J5: FACA
C6: 44011 | E6: BOPP | F6: 2807 | G6: 100X66 | H6: 10.2 | I6: OK | J6: FACA | K6: 100X68 | L6: 2524
A7: TRACIATTI | B7: 44015 | C7: 44014 | D7: 4209 | E7: NYLON | F7: 2600 | G7: 29X76 | H7: 22 | I7: OK | J7: FACA | L7: 875
A8: MAR AZUL | B8: 44014 | C8: 44014 | D8: 4212 | E8: BOPP | F8: 2175 | G8: 30X80 | H8: 2 | I8: OK | J8: lASER | L8: 70
A9: FRIZZO | B9: 44018 | C9: 44022 | D9: 4216 | E9: COUCHE | F9: 869 | G9: 33X25 | H9: 200 | I9: OK | J9: FACA | L9: 720
A10: ESTOQUE | B10: 44021 | C10: 44021 | D10: 4216 | E10: COUCHE | F10: 869 | G10: 33X25 | H10: 95 | I10: OK | J10: FACA | L10: 0
A11: CRIPPA | B11: 44014 | C11: 44013 | D11: 4220 | E11: COUCHE | F11: 1098 | G11: 90X80 | H11: 40 | I11: OK | J11: FACA | L11: 1200
A12: PETRYMAR | B12: 44018 | C12: 44018 | D12: 4222 | E12: COUCHE | F12: 753 | G12: 100X50 | H12: 20 | I12: OK | J12: FACA | L12: 500
A13: IPICARD | B13: 44014 | C13: 44013 | D13: 4224 | E13: BOPP | F13: 1911 | G13: 34X25 | H13: 5 | I13: OK | J13: FACA | K13: 33X25 | L13: 207
A14: INSINUANTE | B14: 44015 | C14: 44015 | D14: 4218 | E14: COUCHE | F14: 616 | G14: 40X30 | H14: 50 | I14: OK | J14: LASER
E15: AMARELO | F15: 2040 | G15: 40X30 | H15: 45 | I15: OK | J15: LASER | L15: 615
A16: DUKE | B16: 44019 | C16: 44014 | D16: 4232 | E16: COUCHE | F16: 2800 | G16: 45X45 | H16: 4.4 | I16: OK | J16: LASER | K16: PERS | L16: 104
A17: URSULA | B17: 44019 | C17: 44018 | D17: 4233 | E17: BOPP | F17: 3219 | G17: 109X25 | H17: 10.5 | I17: OK | J17: LASER | L17: 460
A18: AFETTO | B18: 44020 | C18: 44015 | D18: 4234 | E18: COUCHE | F18: 879 | G18: 100X60 | H18: 10 | I18: OK | J18: FACA
E19: REMOV | F19: 2983 | G19: 100X60 | H19: 25 | I19: OK | J19: FACA
E20: REMOV | F20: 3179 | G20: 80X40 | H20: 5 | I20: OK | J20: LASER | L20: 1557.5
A21: PANIZZON | B21: 44021 | C21: 44015 | D21: 4239 | E21: COUCHE | F21: 1545 | G21: 100X68 | H21: 2 | I21: OK | J21: FACA
E22: AMARELO | F22: 2447 | G22: 100X68 | H22: 3 | I22: OK | J22: FACA
E23: LARANJA | F23: 2589 | G23: 100X68 | H23: 3 | I23: OK | J23: FACA
E24: AZUL | F24: 2576 | G24: 100X68 | H24: 1 | I24: OK | J24: FACA
E25: VERDE | F25: 2448 | G25: 100X68 | H25: 3 | I25: OK | J25: FACA | L25: 616.6
A26: CORSUL | B26: 44019 | C26: 44019 | D26: 4245 | E26: COUCHE | F26: 2347 | G26: 50X150 | H26: 5 | I26: OK | J26: LASER | L26: 207.3
A27: SULPACK | B27: 44019 | C27: 44018 | D27: 4246 | E27: BOPP | F27: 1401 | G27: 50X22 | H27: 9 | I27: OK | J27: LASER | L27: 335
A28: BIOLUZ | B28: 44020 | D28: 4247 | E28: BOPP | F28: 3131 | G28: 35X40 | H28: 30 | I28: OK | J28: FACA | L28: 453.6
A29: ESTOQUE | B29: 44018 | E29: BOPP | F29: 1095 | G29: 100X50 | H29: 7.2 | I29: OK | J29: FACA | L29: 0
A30: TEODORO | B30: 44020 | C30: 44019 | D30: 4250 | E30: COUCHE | F30: 1140 | G30: 44X16 | H30: 20 | I30: OK | J30: LASER
E31: POLIESTER | F31: 1019 | G31: 34X51 | H31: 6 | I31: OK | J31: LASER | L31: 586
A32: FRIZZO | B32: 44020 | C32: 44019 | D32: 4260 | E32: TAG | F32: 2708 | G32: 33X145 | H32: 3 | I32: OK | J32: LASER | L32: 55.5
A33: FRIZZO | B33: 44021 | C33: 44019 | D33: 4261 | E33: BOPP | F33: 3129 | G33: 50X18 | H33: 8 | I33: OK | J33: LASER | L33: 71.6
A34: DI FARR | B34: 44021 | C34: 44020 | D34: 4262 | E34: COUCHE | F34: 1397 | G34: 50X30 | H34: 50 | I34: OK | J34: FACA | L34: 470
A35: BARAO | B35: 44022 | C35: 44020 | D35: 4263 | E35: COUCHE | F35: 2577 | G35: 100X40 | H35: 3 | I35: OK | J35: FACA | K35: PERS | L35: 69
A36: SIMONE FRANCO | B36: 44025 | C36: 44019 | D36: 4264 | E36: NYLON | F36: 2600 | G36: 29X76 | H36: 16.5 | I36: OK | J36: FACA | M36: 4.000 OK
A37: FRIZZO | B37: 44025 | C37: 44019 | D37: 0 | E37: COUCHE | F37: 1468 | G37: 100X75 | H37: 20 | I37: OK | J37: FACA | L37: REPOR
A38: FRIZZO | B38: 44025 | C38: 44019 | D38: 4269 | E38: BOPP | F38: 2724 | G38: 25X16 | H38: 10 | I38: OK | J38: FACA | L38: 45.5
A39: FRIZZO | B39: 44027 | C39: 44018 | D39: 4063 | E39: COUCHE | F39: 1869 | G39: 33X21 | H39: 80 | I39: OK | J39: FACA | L39: 264
A40: HOSP. SC | B40: 44029 | D40: 4271 | E40: COUCHE | F40: 843 | G40: 34X23 | H40: 200 | I40: OK | J40: FACA | K40: NOVA
...

Sheet AGOSTO20
A1: CLIENTE | B1: Data Entr | C1: Data Prod | D1: O/F | E1: MATERIAL | F1: CÓDIGO | G1: ETIQUETA | H1: QUANT | I1: OK | J1: PRODUZIDO POR | K1: O/C | L1: VALOR
A2: CRIPPA | B2: 44043 | C2: 44043 | D2: 4517 | E2: COUCHE | F2: 1098 | G2: 90X80 | H2: 40 | I2: OK | J2: FACA | L2: 1200
A3: CARRARO | B3: 44046 | C3: 07/0/8 | D3: 4399 | E3: COUCHE | F3: 2263 | G3: 65X197 | H3: 11.4 | I3: OK | J3: G10 | K3: 1478 | L3: 1060
A4: VICENZI | B4: 44048 | C4: 44050 | D4: 4418 | E4: COUCHE | F4: 940 | G4: 90X20 | H4: 50.5 | I4: OK | J4: G10 | K4: 1479 | L4: 905
A5: SUPER PECAS | B5: 44048 | C5: 44050 | D5: 4443 | E5: COUCHE | F5: 1153 | G5: 25X54 | H5: 64.5 | I5: OK | J5: G10 | K5: 1480 | L5: 450
A6: CENTRA | B6: 44047 | D6: 4449 | E6: COUCHE | F6: 2691 | G6: 100X50 | H6: 5 | I6: OK | J6: FACA/LASER | K6: PICOTAR | L6: 210
A7: HYVA | B7: 44048 | C7: 44046 | D7: 4468 | E7: TAG | F7: 2550 | G7: 100X70 | H7: 10 | I7: OK | J7: LASER | L7: 405
A8: SULPACK | B8: 44048 | C8: 44047 | D8: 4480 | E8: BOPP | F8: 1170 | G8: 100X30 | H8: 5 | I8: OK | J8: LASER
E9: BOPP | F9: 1169 | G9: 100X30 | H9: 2 | I9: OK | J9: LASER
E10: BOPP | F10: 3215 | G10: 12X20 | H10: 3 | I10: OK | J10: LASER
E11: BOPP | F11: 1157 | G11: 15X15 | H11: 3 | I11: OK | J11: LASER
E12: COUCHE | F12: 838 | G12: 100X40 | H12: 1 | I12: OK | J12: FACA | L12: 629.5
A13: CEMTRA | B13: 44049 | C13: 44049 | D13: 4449 | E13: COUCHE | F13: 2691 | G13: 100X50 | H13: 5 | I13: OK | J13: FACA/LASER
F14: 2971 | G14: 100X48 | H14: 1 | I14: OK | J14: LASER | L14: 249
A15: FRIZZO | B15: 44050 | C15: 44048 | D15: 4495 | E15: COUCHE | F15: 1467 | G15: 85X50 | H15: 4.5 | I15: OK | J15: LASER | L15: 87.75
A16: FRIZZO | B16: 44050 | C16: 44055 | D16: 4493 | E16: COUCHE | F16: 2186 | G16: 90X40 | H16: 50 | I16: OK | J16: FACA | L16: 637.5
A17: FRIZZO | B17: 44049 | C17: 44047 | D17: 4494 | E17: COUCHE | F17: 1468 | G17: 100X75 | H17: 15 | I17: OK | J17: FACA | L17: 433.5
A18: ARCO COMPON. | B18: 44050 | C18: 44060 | D18: 4502 | E18: COUCHE | F18: 2604 | G18: 105X55 | H18: 21.2 | I18: OK | J18: G10 | K18: 1483 | L18: 434
B19: 44054 | C19: 44054 | F19: 2604 | G19: 105X55 | H19: 12.4 | I19: OK | J19: ESTOQUE
A20: VIA HOMEM | B20: 44050 | C20: 44063 | D20: 4505 | E20: COUCHE | F20: 2040 | G20: 40X30 | H20: 57.5 | I20: OK | J20: G10 | K20: 1482 | L20: 203
A21: MCC | B21: 44050 | C21: 44048 | D21: 4509 | E21: C.BORR | F21: 2491 | G21: 100X90 | H21: 5.2 | I21: OK | J21: LASER | L21: 226.3
A22: ENOMAK | B22: 44050 | C22: 44049 | D22: 4519 | E22: TAG | F22: 1316 | G22: 95X30 | H22: 6.25 | I22: OK | J22: LASER | L22: 143.75
A23: LAMINA | B23: 44053 | C23: 44048 | D23: 4408 | E23: COUCHE | F23: 885 | G23: 70X50 | H23: 55.3 | I23: OK | J23: FACA | L23: 450
A24: FRIZZO | B24: 44027 | C24: 44047 | D24: 4064 | E24: COUCHE | F24: 1869 | G24: 33X21 | H24: 90 | I24: OK | J24: FACA | L24: 264
A25: PLASMOSUL | B25: 44053 | C25: 44053 | D25: 4560 | E25: COUCHE | F25: 3239 | G25: 90X40 | H25: 2 | I25: OK | J25: FACA/LASER | L25: 79.8
E26: COUCHE | F26: 1186 | G26: 100X60 | H26: 2 | I26: OK | J26: LASER
A27: PLASTK | B27: 44053 | C27: 44050 | D27: 4522 | E27: COUCHE | F27: 744 | G27: 100X70 | H27: 10 | I27: OK | J27: LASER | L27: 385
A28: SERRANORTE | B28: 44054 | C28: 44049 | D28: 4524 | E28: COUCHE | F28: 2703 | G28: 55X34 | H28: 11.25 | I28: OK | J28: LASER
E29: COUCHE | F29: 753 | G29: 100X50 | H29: 10.4 | I29: OK | J29: FACA | L29: 423.25
A30: EBS | B30: 44054 | C30: 44053 | D30: 4525 | E30: B.BORR | F30: 2329 | G30: 105X105 | H30: 4 | I30: OK | J30: LASER | L30: 474.8
A31: DOLCE VITA | B31: 44054 | C31: 44056 | D31: 4527 | E31: COUCHE | F31: 3005 | G31: 90X60 | H31: 8 | I31: OK | J31: LASER
E32: COUCHE | F32: 3078 | G32: 75X27 | H32: 15 | I32: OK | J32: LASER
E33: COUCHE | F33: 3080 | G33: 50X15 | H33: 14 | I33: OK | J33: LASER | L33: 524.8
A34: GRANVIN | B34: 44050 | C34: 44047 | D34: 4534 | E34: COUCHE | F34: 2971 | G34: 100X48 | H34: 6.4 | I34: OK | J34: LASER | L34: 157.8
A35: SUPERLACK | B35: 44046 | C35: 44046 | D35: 4538 | E35: COUCHE | F35: 838 | G35: 100X40 | H35: 5 | I35: OK | J35: FACA | L35: 115
A36: CODETECH | B36: 44047 | C36: 44047 | D36: 4537 | E36: COUCHE | F36: 869 | G36: 33X25 | H36: 95 | I36: OK | J36: RETIRADO | K36: ESTOQUE | L36: 427.5
A37: BANCO SANGUE | B37: 44055 | C37: 44056 | D37: 4542 | E37: BOPP | F37: 1607 | G37: 50X50 | H37: 4.5 | I37: OK | J37: FACA
E38: BOPP | F38: 3241 | G38: 105X105 | H38: 2 | I38: OK | J38: LASER | L38: 226.72
A39: BVN | B39: 44055 | C39: 44048 | D39: 4544 | E39: COUCHE | F39: 753 | G39: 100X50 | H39: 2.4 | I39: OK | J39: FACA | L39: 76
A40: MACRUZ | B40: 44055 | C40: 44062 | D40: 4548 | E40: BOPP | F40: 3242 | G40: 100X45 | H40: 6.4 | I40: OK | J40: LASER | M40: AMOSTRAS | N40: 44057
...

Sheet SETEMBRO20
A1: CLIENTE | B1: Data Entr | C1: Data Prod | D1: O/F | E1: MATERIAL | F1: CÓDIGO | G1: ETIQUETA | H1: QUANT | I1: OK | J1: PRODUZIDO POR | K1: O/C | L1: VALOR
A2: REZLER | B2: 44075 | C2: 44075 | D2: 4696 | E2: BOPP BORR | F2: 2640 | G2: 80X60 | H2: 10.4 | I2: OK | J2: LASER | L2: 395
A3: AMF | B3: 44076 | C3: 44075 | D3: 4707 | E3: COUCHE | F3: 869 | G3: 33X25 | H3: 200 | I3: OK | J3: FACA | L3: 720
A4: JS SERVS | B4: 44077 | C4: 44076 | D4: 4723 | E4: COUCHE | F4: 1173 | G4: 100X25 | H4: 18 | I4: OK | J4: LASER | L4: 351
A5: HYVA | B5: 44077 | C5: 44077 | D5: 4724 | E5: TAG | F5: 2550 | G5: 100X70 | H5: 20 | I5: OK | J5: LASER | L5: 810
A6: DUKE | B6: 44077 | C6: 44077 | D6: 4728 | E6: COUCHE | F6: 2800 | G6: 45X45 | H6: 4 | I6: OK | J6: LASER | K6: PERS | L6: 208
B7: 44077 | C7: 44077 | F7: 2891 | G7: 60X60 | H7: 2 | I7: OK | J7: LASER | K7: PERS | L7: 130
A8: IND.FER.LAZZ | B8: 44077 | C8: 44078 | D8: 4729 | E8: COUCHE | F8: 1173 | G8: 100X25 | H8: 21 | I8: OK | J8: LASER | L8: 730
A9: AMF | B9: 44082 | C9: 44077 | D9: 4643 | E9: COUCHE | F9: 879 | G9: 100X60 | H9: 50.4 | I9: OK | J9: FACA | L9: 1050
A10: HYVA | B10: 44082 | C10: 44082 | D10: 4757 | E10: TAG | F10: 2550 | G10: 100X70 | H10: 30 | I10: OK | J10: LASER | L10: 1215
A11: G3 | B11: 44082 | C11: 44082 | D11: 4759 | E11: BOPP | F11: 3139 | G11: 78X25 | H11: 5 | I11: OK | J11: LASER | L11: 108.5
A12: LC SOLUCOES | B12: 44083 | C12: 44091 | D12: 4760 | E12: COUCHE | F12: 3268 | G12: 102X34 | H12: 50 | I12: OK | J12: LASER | L12: 850
A13: MATRIMETAL | B13: 44082 | C13: 44082 | D13: 4800 | E13: COUCHE | F13: 2022 | G13: 80X30 | H13: 11 | I13: OK | J13: LASER | L13: 228
A14: BP COMP | B14: 44082 | C14: 44085 | D14: 4746 | E14: POLIESTER | F14: 1183 | G14: 30X15 | H14: 7.2 | I14: OK | J14: LABEL | K14: 1496 | L14: 1300
A15: BANCO SANGUE | B15: 44084 | C15: 44076 | D15: 4798 | E15: BOPP | F15: 1607 | G15: 50X50 | H15: 3 | I15: OK | J15: FACA | L15: 33.6
E16: BOPP | F16: 2467 | G16: 100X80 | H16: 2 | I16: OK | J16: FACA | L16: 216
A17: LAMINA | B17: 44084 | C17: 44076 | D17: 4307 | E17: COUCHE | F17: 885 | G17: 70X50 | H17: 40.6 | I17: OK | J17: FACA | L17: 600
A18: LAMINA | B18: 44084 | C18: 44082 | D18: 4833 | E18: COUCHE | F18: 855 | G18: 70X50 | H18: 35.7 | I18: OK | J18: FACA | L18: 535.5 | M18: FAZER PARA FECHA OS 80.000
A19: HOZANE | B19: 44084 | C19: 44084 | D19: 4788 | E19: COUCHE | F19: 728 | G19: 35X25 | H19: 4.5 | I19: OK | J19: LASER | L19: 42.75
A20: FLORENZA | B20: 44084 | C20: 44088 | D20: 4749 | E20: COUCHE | F20: 1862 | G20: 100X35 | H20: 10 | I20: OK | J20: LASER | L20: 210
A21: LAIMED | B21: 44076 | C21: 44076 | D21: 4808 | E21: COUCHE | F21: 1098 | G21: 90X80 | H21: 3 | I21: OK | J21: FACA | L21: 37.12
A22: HOSP.SAO CARL | B22: 44088 | C22: 44088 | D22: 4807 | E22: BOPP | F22: 1491 | G22: 100X23 | H22: 10 | I22: OK | J22: LASER
C23: 44083 | E23: AMARELO | F23: 3162 | G23: 34X23 | H23: 40 | I23: OK | J23: FACA
E24: COUCHE | F24: 843 | G24: 34X23 | H24: 120 | I24: OK | J24: FACA
E25: VERM | F25: 3163 | G25: 34X23 | H25: 120 | I25: OK | J25: FACA | L25: 1853.8
A26: STELLALBLU | B26: 44088 | C26: 44089 | D26: 4809 | E26: PROMOM | F26: 1019 | G26: 34X51 | H26: 6 | I26: OK | J26: LASER
E27: COUCHE | F27: 1924 | G27: 44X16 | H27: 4 | I27: OK | J27: LASER | L27: 210
A28: BRASSUD | B28: 44085 | C28: 44077 | D28: 4813 | E28: COUCHE | F28: 1960 | G28: 35X40 | H28: 21 | I28: OK | J28: FACA | L28: 406
A29: SEXY FANTASY | B29: 44083 | C29: 44078 | D29: 4816 | E29: COUCHE | F29: 1087 | G29: 28X55 | H29: 62.5 | I29: OK | J29: FACA
C30: 44077 | E30: COUCHE | F30: 2639 | G30: 15X30 | H30: 32 | I30: OK | J30: FACA | L30: 735
A31: TOP LIMP | B31: 44088 | D31: 4818 | E31: COUCHE | F31: 2515 | G31: 55X28 | H31: 10 | I31: OK | J31: FACA
E32: AMARELO | F32: 2765 | G32: 55X28 | H32: 5 | I32: OK | J32: FACA | L32: 60.75
A33: SULPACK | B33: 44088 | C33: 44089 | D33: 4819 | E33: BOPP | F33: 1401 | G33: 55X22 | H33: 2 | I33: OK | J33: LASER | L33: 70
C34: 44082 | E34: COUCHE | F34: 838 | G34: 100X40 | H34: 1 | I34: OK | J34: FACA | L34: 24
C35: 44082 | E35: BOPP | F35: 1395 | G35: 50X20 | H35: 7 | I35: OK | J35: FACA | L35: 180
A36: SUPER AR | B36: 44088 | C36: 44078 | D36: 4820 | E36: COUCHE | F36: 1468 | G36: 100X75 | H36: 4 | I36: OK | J36: FACA | L36: 236
A37: JC | B37: 44084 | D37: 4824 | E37: AMARELO | F37: 3273 | G37: 33X25 | H37: 3 | I37: OK | J37: FACA | K37: PERS
E38: AMARELO | F38: 3272 | G38: 33X25 | H38: 20 | I38: OK | J38: FACA | K38: PERS
E39: AMARELO | F39: 3029 | G39: 33X25 | H39: 7 | I39: OK | J39: FACA | K39: PERS | L39: 309
A40: AMF | B40: 44089 | C40: 44090 | D40: 4717 | E40: COUCHE | F40: 3264 | G40: 33X22 | H40: 30 | I40: OK | J40: G10 | K40: 1493 | L40: 135
...

Sheet FACA BATIDA
B2: FACAS DE BATIDA
B3: COD | C3: FACA | D3: COL | E3: QTD/ROLO | F3: METROS
C4: 16x6 | D4: 4
C5: 25X75 | D5: 4 | E5: 500 | F5: 39
C6: 30X15 | D6: 3 | E6: 7000 | F6: 42
C7: 30X22 | D7: 3 | E7: 4500 | F7: 38
C8: 30X30 | D8: 3 | E8: 4000 | F8: 44
C9: 32x11 | D9: 3 | E9: 10000 | F9: 47
C10: 32x55 | D10: 3 | E10: 1500 | F10: 29
C11: 33X10 | D11: 3 | E11: 5000 | F11: 23
C12: 33x17 | D12: 3 | E12: 6000 | F12: 40
C13: 33X25 | D13: 3 | E13: 5000 | F13: 47
C14: 33X37 | D14: 2
C15: 33X39 | D15: 3 | E15: 2000 | F15: 28
C16: 33x49 | D16: 3 | E16: 2000 | F16: 52
C17: 35X26,5 | D17: 3 | E17: 4000 | F17: 40
C18: 40X25 | D18: 2 | E18: 2000 | F18: 28
C19: 40X34 | D19: 1 | E19: 2500 | F19: 92
C20: 40X34 | D20: 2 | E20: 2000 | F20: 37
C21: 44X60 | D21: 2 | E21: 1250 | F21: 39
C22: 45x20 | D22: 2 | E22: 3500 | F22: 40
C23: 45x25 | D23: 2 | E23: 2000 | F23: 28
C24: 50x15 | D24: 2 | E24: 4000 | F24: 36
C25: 50X18 | D25: 2 | E25: 4000 | F25: 42
C26: 50x22 | D26: 2 | E26: 3500 | F26: 44
C27: 50X25 | D27: 2 | E27: 3000 | F27: 42
C28: 52X20 | D28: 2
C29: 55X25 | D29: 1 | E29: 2000 | F29: 56
C30: 55X28 | D30: 1 | E30: 1500 | F30: 46
C31: 56X23 | D31: 1 | E31: 2000 | F31: 52
C32: 60x20 | D32: 1 | E32: 2000 | F32: 65
C33: 60X30 | D33: 1 | E33: 1250 | F33: 41
C34: 66X25 | D34: 1 | E34: 3500 | F34: 98
C35: 70X40 | D35: 1 | E35: 1000 | F35: 43
C36: 72x17 | D36: 1 | E36: 2000 | F36: 40
C37: 74X74 | D37: 1 | E37: 1000 | F37: 77
C38: 78x30 | D38: 1 | E38: 1250 | F38: 41
C39: 80X25 | D39: 1 | E39: 1500 | F39: 42
C40: 80x30 | D40: 1 | E40: 1250 | F40: 41
... C49: 90X90 | D49: 1 | E49: 500 | F49: 46
...

Sheet FACAS
B2: Facas Rotativas | J2: Para cálculo
B3: COD | C3: PAPEL | D3: FACA - col | E3: VALOR | F3: PAPEL/ESP | G3: QUANT | H3: METROS | J3: M/MILHEIRO | K3: LARG PAPEL
B5: 2825 | C5: COUCHE ACRILICO | D5: 106X85 - 1 | E5: =(J5*K5*PRECOS!N21) -> 29.0675 | F5: 110/87,5 | G5: 500 | H5: 44 | J5: 87.5 | K5: 0.11
B7: 3241 | C7: BOPP ACRILICO | D7: 105x105 - 1 | E7: =(J7*K7*PRECOS!#REF!) -> #REF! | F7: 110/108 | G7: 400 | H7: 43 | J7: 108 | K7: 0.11
B9: 2604 | C9: COUCHE ACRILICO | D9: 105x55 - 1 | E9: =(J9*K9*PRECOS!#REF!) -> #REF! | F9: 110/57 | G9: 800 | H9: 46 | J9: 57 | K9: 0.11
B11: 3286 | C11: COUCHE ACRILICO | D11: 103X93 - 1 | E11: =(J11*K11*PRECOS!N21) -> 31.7251 | F11: 110/95,5 | G11: 1000 | H11: 95 | J11: 95.5 | K11: 0.11
B13: 951 | C13: COUCHE ACRILICO | D13: 100X150 - 1 | E13: =(J13*K13*PRECOS!N21) -> 48.5163 | F13: 105/153 | G13: 250 | H13: 38 | J13: 153 | K13: 0.105
B14: 2847 | C14: TERMICO | D14: 100X150 - 1 | E14: =(J14*K14*PRECOS!N22) -> 47.71305 | F14: 105/153 | G14: 250 | H14: 38 | J14: 153 | K14: 0.105
B15: 1446 | C15: BOPP ACRÍLICO | D15: 100X150 - 1 | E15: =(J15*K15*PRECOS!#REF!) -> #REF! | F15: 105/153 | G15: 250 | H15: 38 | J15: 153 | K15: 0.105
C17: BOPP BORRACHA | D17: 100X120 - PICOTE
B19: 1126 | C19: COUCHE ACRILICO | D19: 100X100 - 1 | E19: =(J19*K22*PRECOS!N21) -> 32.6613 | F19: 105/103 | G19: 400 | H19: 42 | J19: 103 | K19: 0.105
B20: 1408 | C20: BOPP ACRILICO | D20: 100X100 - 1 | E20: =(J20*K23*PRECOS!#REF!) -> #REF! | F20: 105/103 | G20: 400 | H20: 42 | J20: 103 | K20: 0.105
B22: 2761 | C22: COUCHE ACRILICO | D22: 100X80 - 1 | E22: =(J22*K22*PRECOS!N21) -> 26.3193 | F22: 105/83 | G22: 500 | H22: 42 | J22: =83/1 -> 83 | K22: 0.105
B23: 788 | C23: COUCHE BORRACHA | D23: 100X80 - 1 | E23: =(J23*K23*PRECOS!N22) -> 25.88355 | F23: 105/83 | G23: 500 | H23: 42 | J23: =83/1 -> 83 | K23: 0.105
B24: 2467 | C24: BOPP ACRILICO | D24: 100X80 - 1 | E24: =(J24*K24*PRECOS!#REF!) -> #REF! | F24: 105/83 | G24: 500 | H24: 42 | J24: =83/1 -> 83 | K24: 0.105
B25: 2468 | C25: BOPP BORRACHA | D25: 100X80 - 1 | E25: =(J25*K25*PRECOS!N23) -> 38.25885 | F25: 105/83 | G25: 500 | H25: 42 | J25: =83/1 -> 83 | K25: 0.105
B26: 2935 | C26: DFAM 430 | D26: 100X80 - 1 | E26: =(J26*K26*PRECOS!N27) -> 52.02855 | F26: 105/83 | G26: 500 | H26: 42 | J26: =83/1 -> 83 | K26: 0.105
B28: 1468 | C28: COUCHE ACRILICO | D28: 100X75 - 1 | E28: =(J28*K28*PRECOS!N21) -> 24.7338 | F28: 105/78 | G28: 500 | H28: 39 | J28: =78/1 -> 78 | K28: 0.105
B29: 2581 | C29: COUCHE BORRACHA | D29: 100X75 - 1 | E29: =(J29*K29*PRECOS!N22) -> 24.3243 | F29: 105/78 | G29: 500 | H29: 39 | J29: =78/1 -> 78 | K29: 0.105
B30: 2050 | C30: BOPP ACRILICO | D30: 100X75 - 1 | E30: =J30*K30*PRECOS!#REF! -> #REF! | F30: 105/78 | G30: 500 | H30: 39 | J30: =78/1 -> 78 | K30: 0.105
B32: 1545 | C32: COUCHE ACRILICO | D32: 100X68 - 1 | E32: =(J32*K32*PRECOS!N21) -> 22.67265 | F32: 105/71,5 | G32: 500 | H32: 36 | J32: =71.5/1 -> 71.5 | K32: 0.105
B33: 2576 | C33: COUCHE ACR COLORIDO | D33: 100X68 - 1 | E33: =(J33*K33*PRECOS!Y21) -> 24.9249 | F33: 105/71,5 | G33: 1000 | H33: 72 | J33: =71.5/1 -> 71.5 | K33: 0.105
B34: 2589 | C34: COUCHE BORR COLORIDO | D34: 100X68 - 1 | E34: =(J34*K34*PRECOS!Y22) -> 24.549525 | F34: 105/71,5 | G34: 500 | H34: 36 | J34: =71.5/1 -> 71.5 | K34: 0.105
B36: 879 | C36: COUCHE ACRILICO | D36: 100X60 - 1 | E36: =(J36*K36*PRECOS!N21) -> 19.81875 | F36: 105/62,5 | G36: 700 | H36: 44 | J36: =62.5/1 -> 62.5 | K36: 0.105
B37: 2244 | C37: COUCHE BORRACHA | D37: 100X60 - 1 | E37: =(J37*K37*PRECOS!N22) -> 19.490625 | F37: 105/62,5 | G37: 700 | H37: 44 | J37: =62.5/1 -> 62.5 | K37: 0.105
B38: 1363 | C38: BOPP ACRILICO | D38: 100X60 - 1 | E38: =(J38*K38*PRECOS!#REF!) -> #REF! | F38: 105/62,5 | G38: 700 | H38: 44 | J38: =62.5/1 -> 62.5 | K38: 0.105
B39: 2948 | C39: COUCHE TÉRMICO | D39: 100X60 - 1 | E39: =(J39*K39*PRECOS!#REF!) -> #REF! | F39: 105/62,5 | G39: 700 | H39: 44 | J39: =62.5/1 -> 62.5 | K39: 0.105
B40: 2983 | C40: COUCHE REMOVIVEL | D40: 100X60 - 1 | E40: =(J40*K40*PRECOS!#REF!) -> #REF! | F40: 105/62,5 | G40: 700 | H40: 44 | J40: =62.5/1 -> 62.5 | K40: 0.105
B41: 1403 | C41: COUCHE COLORIDO | D41: 100X60 - 1 | E41: =(J41*K41*PRECOS!Y21) -> 21.7875 | F41: 105/62,5 | G41: 700 | H41: 44 | J41: =62.5/1 -> 62.5 | K41: 0.105
B43: 753 | C43: COUCHE ACRILICO | D43: 100X50 - 1 | E43: =(J43*K43*PRECOS!N21) -> 16.8063 | F43: 105/53 | G43: 800 | H43: 42 | J43: =53/1 -> 53 | K43: 0.105
B44: 2438 | C44: COUCHE BORRACHA | D44: 100X50 - 1 | E44: =(J44*K44*PRECOS!N22) -> 16.52805 | F44: 105/53 | G44: 800 | H44: 42 | J44: =53/1 -> 53 | K44: 0.105
B45: 1376 | C45: COUCHE COLORIDO | D45: 100X50 - 1 | E45: =(J45*K45*PRECOS!Y21) -> 18.4758 | F45: 105/53 | G45: 800 | H45: 42 | J45: =53/1 -> 53 | K45: 0.105
B46: 1477 | C46: COUCHE REMOVIVEL | D46: 100X50 - 1 | E46: =(J46*K46*PRECOS!#REF!) -> #REF! | F46: 105/53 | G46: 800 | H46: 42 | J46: =53/1 -> 53 | K46: 0.105
B47: 1095 | C47: BOPP ACRILICO | D47: 100X50 - 1 | E47: =(J47*K47*PRECOS!#REF!) -> #REF! | F47: 105/53 | G47: 1000 | H47: 53 | J47: =53/1 -> 53 | K47: 0.105
B48: 3096 | C48: BOPP BORRACHA | D48: 100X50 - 1 | E48: =(J48*K48*PRECOS!N23) -> 24.43035 | F48: 105/53 | G48: 1000 | H48: 53 | J48: =53/1 -> 53 | K48: 0.105
B50: 3500 | C50: COUCHE ACRILICO | D50: 100X45 - 1 | E50: =(J50*K50*PRECOS!N27) -> 30.0888 | F50: 105/48 | G50: 1000 | H50: 48 | J50: 48 | K50: 0.105
B52: 838 | C52: COUCHE ACRILICO | D52: 100X40 - 1 | E52: =(J52*K52*PRECOS!N21) -> 13.6353 | F52: 105/43 | G52: 1000 | H52: 43 | J52: =43/1 -> 43 | K52: 0.105
B53: 2590 | C53: COUCHE BORRACHA | D53: 100X40 - 1 | E53: =(J53*K53*PRECOS!N22) -> 13.40955 | F53: 105/43 | G53: 1000 | H53: 43 | J53: =43/1 -> 43 | K53: 0.105
B54: 1483 | C54: BOPP ACRILICO | D54: 100X40 - 1 | E54: =(J54*K54*PRECOS!#REF!) -> #REF! | F54: 105/43 | G54: 1000 | H54: 43 | J54: =43/1 -> 43 | K54: 0.105
B55: 2560 | C55: BOPP BORRACHA | D55: 100X40 - 1 | E55: =(J55*K55*PRECOS!N23) -> 19.82085 | F55: 105/43 | G55: 1000 | H55: 43 | J55: =43/1 -> 43 | K55: 0.105
...

Sheet ABRIL20
A1: CLIENTE | B1: Data Entr | C1: Data Prod | D1: OC | E1: MATERIAL | F1: CÓDIGO | G1: ETIQUETA | H1: QUANT | I1: OK | J1: PRODUZIDO?
A2: PRO MARMO | B2: ??? | D2: 3487 | E2: BOPP | F2: 3127 | G2: 103X200 | H2: 200 | I2: OK | J2: ESPERAR | K2: ENVIADO AMOSTRA | L2: OK
A3: PORTAL USINAGEM | B3: 43913 | C3: 43935 | D3: 3571 | E3: TAG | F3: 3134 | G3: 95X39 | H3: 20000 | I3: OK | J3: LASER
A4: FRIZZO | B4: 43922 | C4: 43935 | D4: 3549 | E4: COUCHE | F4: 869 | G4: 33X25 | H4: 120000 | I4: OK | J4: FACA
A5: FRIZZO | B5: 43906 | C5: 43934 | D5: 3492 | E5: BOPP | F5: 3129 | G5: 50X18 | H5: 100000 | I5: OK
B6: 43903 | C6: 43908 | D6: 1418 | E6: BOPP | F6: 3129 | G6: 50X18 | H6: 52000 | I6: OK | J6: VITORIA
B7: 43903 | C7: 43934 | D7: 1418 | E7: BOPP | F7: 3129 | G7: 50X18 | H7: 48000 | I7: OK | J7: VITORIA
A8: DIAN | B8: 43910 | C8: 43934 | D8: 3558 | E8: COUCHE | F8: 1215 | G8: 40X34 | H8: 10000 | I8: OK
B9: 43910 | C9: 43934 | D9: 1429 | E9: COUCHE | F9: 1215 | G9: 40X34 | H9: 50000 | I9: OK | J9: VITORIA
A10: PLASMOSUL | B10: 43915 | C10: 43934 | D10: 3584 | E10: COUCHE | F10: 1186 | G10: 100X66 | H10: 9500 | I10: OK
B11: 43915 | C11: 43934 | D11: 1432 | E11: COUCHE | F11: 1186 | G11: 100X66 | H11: 9500 | I11: OK | J11: VITORIA
A12: CARRARO | B12: 43914 | C12: 43934 | D12: 3597 | E12: COUCHE | F12: 2263 | G12: 65X197 | H12: 10000 | I12: OK
B13: 43914 | C13: 43934 | D13: 1425 | E13: COUCHE | F13: 2263 | G13: 65X197 | H13: 10100 | I13: OK | J13: VITORIA
A14: RESET | B14: 43916 | C14: 43934 | D14: 3601 | E14: COUCHE | F14: 1173 | G14: 100X25 | H14: 18000 | I14: OK
B15: 43916 | C15: 43934 | D15: 1433 | E15: COUCHE | F15: 1173 | G15: 100X25 | H15: 19500 | I15: OK | J15: VITORIA
A16: JULIAS CLOSET | B16: 43916 | C16: 43934 | D16: 3608 | E16: COUCHE | F16: 1104 | G16: 20X38 | H16: 8000 | I16: OK
B17: 43916 | C17: 43934 | D17: 1434 | E17: COUCHE | F17: 1104 | G17: 20X38 | H17: 20000 | I17: OK | J17: VITORIA
A18: BARAO | B18: 43916 | C18: 43934 | D18: 3596 | E18: COUCHE | F18: 2410 | G18: 45X25 | H18: 10000 | I18: OK
B19: 43916 | C19: 43934 | D19: 1436 | E19: COUCHE | F19: 2410 | G19: 45X25 | H19: 10000 | I19: OK | J19: VITORIA
A20: FERPLAST | B20: 43920 | C20: 43934 | D20: 3630 | E20: COUCHE | F20: 1215 | G20: 40X34 | H20: 30000 | I20: OK
B21: 43910 | C21: 43934 | D21: 1429 | E21: COUCHE | F21: 1215 | G21: 40X34 | H21: 40000 | I21: OK | J21: VITORIA | P21: PAPEL | Q21: TAM | R21: M
A22: DIAN | B22: 43910 | C22: 43936 | D22: 3558 | E22: COUCHE | F22: 1513 | G22: 50X80 | H22: 1000 | I22: OK | J22: LASER | P22: COU.ACR | Q22: 110 | R22: 83
A23: G3 | B23: 43915 | C23: 43936 | D23: 3595 | E23: BOPP | F23: 3139 | G23: 78X25 | H23: 200 | I23: OK | J23: LASER | P23: BOPP | Q23: 85 | R23: 10
A24: INJET | B24: 43917 | C24: 43937 | D24: 3620 | E24: COUCHE | F24: 97 | G24: 80X90 | H24: 500 | I24: OK | J24: LASER | P24: COU.ACR | Q24: 85 | R24: 50
A25: PAPARASO | B25: 43920 | C25: 43941 | D25: 3631 | E25: COUCHE | F25: 2029 | G25: 35X30 | H25: 10000 | I25: OK | J25: LASER | N25: 2 | P25: COU.ACR | Q25: 110 | R25: 110
A26: RIO PRATA | B26: 43938 | C26: 43936 | D26: 3632 | E26: COUCHE | F26: 885 | G26: 70X50 | H26: 5600 | I26: OK | J26: FACA | P26: COU.ACR | Q26: 75 | R26: 270
A27: MCC | B27: 43941 | C27: 43938 | D27: 3658 | E27: C.BORR | F27: 2491 | G27: 100X90 | H27: 5000 | I27: OK | J27: LASER | N27: 1 | P27: COU.BORR | Q27: 105 | R27: 470
A28: PANIZZON | B28: 43938 | C28: 43937 | D28: 3569 | E28: COUCHE | F28: 1545 | G28: 100X68 | H28: 30000 | I28: OK | J28: FACA | P28: COUCHE | Q28: 105 | R28: 220
A29: MERC.MISS | B29: 43943 | C29: 43941 | D29: 3657 | E29: AMARELA | F29: 3149 | G29: 100X30 | H29: 2000 | I29: OK | J29: LASER | N29: 3 | P29: AMARELO | Q29: 105 | R29: 70
A30: ABRIL
A31: AESC | B31: 43908 | C31: 43934 | D31: 3516 | E31: TERMICO | F31: 2873 | G31: 33X22 | H31: 30000 | I31: OK
B32: 43921 | C32: 43934 | D32: 1437 | E32: TERMICO | F32: 2873 | G32: 33X22 | H32: 100000 | I32: OK | J32: VITORIA | K32: AESC
B33: 43921 | C33: 43934 | D33: 1437 | E33: TERMICO | F33: 3150 | G33: 34X23 | H33: 56000 | I33: OK | J33: VITORIA | K33: AESC
B34: 43921 | C34: 43934 | D34: 1437 | E34: TERMICO | F34: 3151 | G34: 70X30 | H34: 15000 | I34: OK | J34: VITORIA | K34: AESC
A35: GAMACOR | B35: 43927 | C35: 43934 | D35: 3568 | E35: COUCHE | F35: 1862 | G35: 100X35 | H35: 15000 | I35: OK
B36: 43913 | C36: 43934 | D36: 1430 | E36: COUCHE | F36: 1862 | G36: 100X35 | H36: 15000 | I36: OK | J36: VITORIA
A37: PORTAL USINAGEM | B37: 43934 | C37: 43934 | D37: 3571 | E37: COUCHE | F37: 1631 | G37: 60X60 | H37: 20250 | I37: OK
B38: 43913 | C38: 43934 | D38: 1431 | E38: COUCHE | F38: 1631 | G38: 60X60 | H38: 20250 | I38: OK | J38: VITORIA
A39: REZLER | B39: 43945 | C39: 43934 | D39: 3537 | E39: BOPP | F39: 2640 | G39: 80X50 | H39: 20000 | I39: OK
B40: 43910 | C40: 43934 | D40: 1428 | E40: BOPP | F40: 2640 | G40: 80X50 | H40: 20400 | I40: OK | J40: VITORIA
...

Sheet MAIO20
A1: CLIENTE | B1: Data Entr | C1: Data Prod | D1: O/F | E1: MATERIAL | F1: CÓDIGO | G1: ETIQUETA | H1: QUANT | I1: OK | J1: PRODUZIDO POR | K1: O/C | L1: VALOR
A2: BP COMPON | B2: 43955 | C2: 43955 | D2: 3641 | E2: POLIESTER | F2: 1183 | G2: 30X15 | H2: 10000 | I2: OK
B3: 43955 | D3: 1450 | H3: 10000 | I3: OK | J3: LABEL | L3: 1049.4
A4: BOI SUL | B4: 43942 | D4: 1443 | E4: BOPP BORR | F4: 2362 | G4: 103X94 | H4: 10000 | L4: CANC
A5: FRIZZO | B5: 43936 | C5: 43957 | D5: 3621 | E5: COUCHE | F5: 1468 | G5: 100X75 | H5: 20000 | I5: OK | J5: FACA
A6: MARTIPLAST | B6: 44071 | D6: 0 | E6: BOPP | F6: 0 | G6: 34X34 | H6: 200 | J6: LASER | K6: ??? | L6: AMOS
E7: BOPP REM | F7: 0 | G7: 34X34 | H7: 200 | J7: LASER | K7: ??? | L7: AMOS
A8: CRIPPA | B8: 43957 | C8: 43955 | D8: 3744 | E8: COUCHE | F8: 1098 | G8: 90X80 | H8: 40000 | I8: OK | J8: FACA | L8: 1200
A9: VITAMED | B9: 43957 | C9: 43956 | D9: 3752 | E9: COUCHE | F9: 838 | G9: 100X40 | H9: 22000 | I9: OK | J9: FACA | L9: 700
A10: FRIZZO | B10: 43958 | C10: 43956 | D10: 3761 | E10: COUCHE | F10: 1468 | G10: 100X75 | H10: 10000 | I10: OK | J10: FACA | L10: 289
A11: FLORENZA | B11: 43958 | C11: 43955 | D11: 3767 | E11: COUCHE | F11: 1862 | G11: 100X30 | H11: 10000 | I11: OK | J11: LASER | L11: 254
A12: LOJA HIP | B12: 43958 | C12: 43959 | D12: 3766 | E12: COUCHE | F12: 1556 | G12: 55X25 | H12: 21000 | I12: OK | J12: JUCA | K12: 1457 | L12: 207
A13: SULPACK | B13: 43959 | C13: 43956 | D13: 3768 | E13: BOPP | F13: 1401 | G13: 50X22 | H13: 6000 | I13: OK | J13: LASER | L13: 210
A14: UNIMED | B14: 43959 | C14: 43956 | D14: 3769 | E14: COUCHE | F14: 2740 | G14: 90X36 | H14: 10000 | I14: OK | J14: FACA | L14: 148
A15: CARGA FACIL | B15: 43962 | C15: 43957 | D15: 3779 | E15: COUCHE | F15: 940 | G15: 90X20 | H15: 5000 | I15: OK | J15: LASER | L15: 22.5
A16: IPICARD | B16: 43962 | C16: 43956 | D16: 3781 | E16: BOPP | F16: 1401 | G16: 50X22 | H16: 18000 | I16: OK | J16: LASER | L16: 288
A17: AGRO. FERR | B17: 43962 | C17: 43958 | D17: 3784 | E17: DFAM | F17: 3165 | G17: 50X10 | H17: 5000 | I17: OK | J17: LASER
C18: 43963 | E18: DFAM | F18: 2935 | G18: 100X80 | H18: 17450 | I18: OK | J18: JUCA | K18: 1458 | L18: 1874
A19: FRIZZO | B19: 43963 | C19: 43959 | D19: 3789 | E19: C.BORR | F19: 3168 | G19: 100X76 | H19: 10000 | I19: OK | J19: LASER | L19: 275.5
A20: BP COMPON | B20: 43963 | C20: 43963 | D20: 3791 | E20: POLIESTER | F20: 1183 | G20: 30X15 | H20: 9000 | I20: OK
D21: 1453 | H21: 9000 | I21: OK | J21: LABEL | L21: 912.6
A22: BANCO SANGUE | B22: 43963 | C22: 43956 | D22: 3792 | E22: BOPP | F22: 2557 | G22: 55X28 | H22: 15500 | I22: OK | J22: FACA | L22: 187.5
A23: INJET | B23: 43963 | C23: 43955 | D23: 3793 | E23: BOPP | F23: 2494 | G23: 25X25 | H23: 15000 | I23: OK | J23: LASER | L23: 550
A24: IMPACOL | B24: 43963 | C24: 43958 | D24: 3801 | E24: COUCHE | F24: 950 | G24: 100X65 | H24: 17000 | I24: OK | J24: JUCA | K24: 1455 | L24: 680
A25: CODETECH | B25: 43964 | C25: 43957 | D25: 3802 | E25: COUCHE | F25: 2690 | G25: 33X25 | H25: 50000 | I25: OK | J25: FACA | L25: 225
A26: G3 | B26: 43964 | C26: 43963 | D26: 3808 | E26: BOPP | F26: 3139 | G26: 78X25 | H26: 5000 | I26: OK | J26: LASER | L26: 108.5
A27: ZANETTI | B27: 43964 | C27: 43959 | D27: 3809 | E27: COUCHE | F27: 1677 | G27: 33X22 | H27: 30000 | I27: OK | J27: JUCA | K27: 1456 | L27: 138
A28: BASFIX | B28: 43964 | C28: 43964 | D28: 3810 | E28: COUCHE | F28: 2733 | G28: 100X75 | H28: 5000 | I28: OK | J28: FACA | K28: PERSONAL
E29: COUCHE | F29: 1468 | G29: 100X75 | H29: 11000 | I29: OK | J29: FACA | L29: 711
A30: FRIZZO | B30: 43959 | C30: 43958 | D30: 3798 | E30: COUCHE | F30: 1545 | G30: 100X68 | H30: 20000 | I30: OK | J30: FACA | L30: 483
A31: FRIZZO | B31: 43964 | C31: 43963 | D31: 3799 | E31: COUCHE | F31: 1139 | G31: 108X87 | H31: 9800 | I31: OK | J31: LASER | L31: 362.5
A32: LESI | B32: 43966 | C32: 43958 | D32: 3824 | E32: BOPP | F32: 1599 | G32: 90X25 | H32: 5000 | I32: OK | J32: FACA | L32: 211
A33: SÃO CARLOS | B33: 43962 | C33: 43963 | D33: 3774 | E33: COUCHE | F33: 3162 | G33: 34X23 | H33: 20000 | I33: OK | J33: JUCA | K33: 1459
F34: 3163 | G34: 34X23 | H34: 20000 | I34: OK | J34: JUCA | K34: 1459 | L34: 322.8
A35: LC | B35: 43963 | C35: 43962 | D35: 3830 | E35: BOPP | F35: 3095 | G35: 100X60 | H35: 10000 | I35: OK | J35: FACA | L35: 508
A36: LC | B36: 43963 | C36: 43962 | D36: 3096 | E36: BOPP | F36: 3096 | G36: 100X50 | H36: 20000 | I36: OK | J36: FACA | L36: 970
A37: RR VISION | B37: 43965 | C37: 43964 | D37: 3829 | E37: BOPP | F37: 2844 | G37: 48X10 | H37: 10000 | I37: OK | J37: LASER | L37: 66
A38: BRICASA | B38: 43965 | C38: 43959 | D38: 3818 | E38: C.BORR | F38: 2481 | G38: 40X15 | H38: 505000 | I38: OK | J38: FACA | L38: 1935
A39: FOODCHAIN | B39: 43966 | C39: 43959 | D39: 3833 | E39: BOPP | F39: 2172 | G39: 33X25 | H39: 30000 | I39: OK | J39: FACA | L39: 327
A40: G3 | B40: 43959 | C40: 43959 | D40: 3842 | E40: COUCHE | F40: 1397 | G40: 50X30 | H40: 35000 | I40: OK | J40: FACA | L40: 280
...

Sheet OUTUBRO20
A1: CLIENTE | B1: Data Entr | C1: Data Prod | D1: O/F | E1: MATERIAL | F1: CÓDIGO | G1: ETIQUETA | H1: QUANT | I1: OK | J1: PRODUZIDO POR | K1: O/C | L1: VALOR
A2: BOFF | B2: 44088 | E2: ROTULO | F2: 3269 | G2: 80X100 | H2: 29.3 | I2: OK | J2: G10 | K2: 1500 | L2: 4834.5
E3: ROTULO | F3: 3270 | G3: 80X100 | H3: 28 | I3: OK | J3: G10 | K3: 1500 | L3: 4620
E4: ROTULO | F4: 3271 | G4: 80X100 | H4: 28.44 | I4: OK | J4: G10 | K4: 1500 | L4: 4692.6
A5: BP COMP | B5: 44112 | C5: 44120 | D5: 4896 | E5: POLIESTER | F5: 1183 | G5: 30X15 | H5: 10 | I5: OK | J5: LABEL | K5: 1512 | L5: 1300
A6: ARCO | B6: 44134 | C6: 44132 | D6: 5164 | E6: COUCHE | F6: 2604 | G6: 105X55 | H6: 21600 | I6: OK | J6: G10 | K6: 1525 | L6: 434
A7: AMF INFO | B7: 44126 | C7: 44127 | D7: 5174 | E7: BOPP | F7: 3129 | G7: 50X18 | H7: 20 | I7: OK | J7: GV | K7: 1528 | L7: 179
A8: ESTERELIZARE | B8: 44126 | C8: 44134 | D8: 5208 | E8: COUCHE | F8: 2691 | G8: 100X50 | H8: 132.8 | I8: OK | J8: GV | K8: 1535 | L8: 2100
A9: AMF INFO | B9: 44125 | C9: 44127 | D9: 5187 | E9: COUCHE | F9: 2646 | G9: 50X35 | H9: 250 | I9: OK | J9: GV | K9: 1527 | L9: 1975
F10: 1350 | G10: 50X35 | H10: 50 | I10: OK | J10: GV | K10: 1527 | L10: 395
A11: DTECH | B11: 44127 | C11: 44134 | D11: 5255 | E11: COUCHE | F11: 1467 | G11: 85X50 | H11: 5.6 | I11: OK | J11: GV | K11: 1530 | L11: 127.5
A12: AMF INFO | B12: 44134 | C12: 44134 | D12: 5227 | E12: COUCHE | F12: 1467 | G12: 85X50 | H12: 5.6 | I12: OK | J12: GV | K12: 1537 | L12: 89.5
A13: IPACOL | B13: 44134 | C13: 44134 | D13: 5304 | E13: COUCHE | F13: 950 | G13: 100X65 | H13: 17 | I13: OK | J13: GV | K13: 1538 | L13: 765
A17: AMF | B17: 44089 | C17: 44109 | D17: 4706 | E17: COUCHE | F17: 3174 | G17: 35X26.5 | H17: 120 | I17: OK | J17: G10 | K17: 1492 | L17: 618
E18: REMOV | F18: 3175 | G18: 35X26.5 | H18: 128 | I18: OK | J18: G10 | K18: 1492 | L18: 774
A19: ECOMETAIS | B19: 44102 | C19: 44111 | D19: 4835 | E19: COUCHE | F19: 1007 | G19: 100X38 | H19: 31.5 | I19: OK | J19: G10 | K19: 1503 | L19: 534
A20: TR CARTUCHOS | B20: 44102 | C20: 44111 | D20: 4832 | E20: COUCHE | F20: 754 | G20: 100x30 | H20: 31.25 | I20: OK | J20: G10 | K20: 1504
